<?xml version="1.0"?>
<robot name="diff_robot" xmlns:xacro="http://www.ros.org/wiki/xacro">

  <!--
    Differential-Drive Robot with 2D LiDAR
    NMPC Goal-Directed Navigation Project
    ME 5659 | Pradeep Sivaa Aiyanar
    Gazebo Harmonic (gz-sim 8.x) compatible
  -->

  <!-- ── Properties ── -->
  <xacro:property name="wheel_radius"  value="0.05"/>
  <xacro:property name="wheel_width"   value="0.04"/>
  <xacro:property name="wheel_sep"     value="0.34"/>
  <xacro:property name="chassis_l"     value="0.28"/>
  <xacro:property name="chassis_w"     value="0.30"/>
  <xacro:property name="chassis_h"     value="0.08"/>
  <xacro:property name="chassis_mass"  value="2.0"/>
  <xacro:property name="wheel_mass"    value="0.1"/>
  <xacro:property name="caster_radius" value="0.025"/>
  <xacro:property name="caster_mass"   value="0.05"/>
  <xacro:property name="lidar_r"       value="0.04"/>
  <xacro:property name="lidar_h"       value="0.04"/>
  <xacro:property name="lidar_mass"    value="0.1"/>

  <!-- ── Inertia macros ── -->
  <xacro:macro name="box_inertia" params="m l w h">
    <inertial>
      <mass value="${m}"/>
      <inertia ixx="${(1/12)*m*(h*h+w*w)}" ixy="0" ixz="0"
               iyy="${(1/12)*m*(l*l+h*h)}" iyz="0"
               izz="${(1/12)*m*(l*l+w*w)}"/>
    </inertial>
  </xacro:macro>

  <xacro:macro name="cylinder_inertia" params="m r h">
    <inertial>
      <mass value="${m}"/>
      <inertia ixx="${(1/12)*m*(3*r*r+h*h)}" ixy="0" ixz="0"
               iyy="${(1/12)*m*(3*r*r+h*h)}" iyz="0"
               izz="${0.5*m*r*r}"/>
    </inertial>
  </xacro:macro>

  <xacro:macro name="sphere_inertia" params="m r">
    <inertial>
      <mass value="${m}"/>
      <inertia ixx="${(2/5)*m*r*r}" ixy="0" ixz="0"
               iyy="${(2/5)*m*r*r}" iyz="0"
               izz="${(2/5)*m*r*r}"/>
    </inertial>
  </xacro:macro>

  <!-- ── Base link (chassis at wheel-axle height) ── -->
  <link name="base_link">
    <visual>
      <origin xyz="0 0 ${chassis_h/2}" rpy="0 0 0"/>
      <geometry><box size="${chassis_l} ${chassis_w} ${chassis_h}"/></geometry>
      <material name="blue"><color rgba="0.2 0.4 0.8 1.0"/></material>
    </visual>
    <collision>
      <origin xyz="0 0 ${chassis_h/2}" rpy="0 0 0"/>
      <geometry><box size="${chassis_l} ${chassis_w} ${chassis_h}"/></geometry>
    </collision>
    <xacro:box_inertia m="${chassis_mass}" l="${chassis_l}" w="${chassis_w}" h="${chassis_h}"/>
  </link>

  <!-- ── Wheel macro ── -->
  <xacro:macro name="wheel" params="name y_sign">
    <link name="${name}">
      <visual>
        <origin xyz="0 0 0" rpy="${pi/2} 0 0"/>
        <geometry><cylinder radius="${wheel_radius}" length="${wheel_width}"/></geometry>
        <material name="dark_grey"><color rgba="0.15 0.15 0.15 1.0"/></material>
      </visual>
      <collision>
        <origin xyz="0 0 0" rpy="${pi/2} 0 0"/>
        <geometry><cylinder radius="${wheel_radius}" length="${wheel_width}"/></geometry>
      </collision>
      <xacro:cylinder_inertia m="${wheel_mass}" r="${wheel_radius}" h="${wheel_width}"/>
    </link>
    <joint name="${name}_joint" type="continuous">
      <parent link="base_link"/>
      <child link="${name}"/>
      <origin xyz="0 ${y_sign * wheel_sep/2} 0" rpy="0 0 0"/>
      <axis xyz="0 1 0"/>
    </joint>
    <gazebo reference="${name}">
      <mu1>1.0</mu1><mu2>0.5</mu2>
      <kp>500000.0</kp><kd>10.0</kd>
      <minDepth>0.001</minDepth><maxVel>0.1</maxVel>
    </gazebo>
  </xacro:macro>

  <xacro:wheel name="left_wheel"  y_sign="1"/>
  <xacro:wheel name="right_wheel" y_sign="-1"/>

  <!-- ── Caster wheel ── -->
  <link name="caster_wheel">
    <visual>
      <origin xyz="0 0 0" rpy="0 0 0"/>
      <geometry><sphere radius="${caster_radius}"/></geometry>
      <material name="grey"><color rgba="0.5 0.5 0.5 1.0"/></material>
    </visual>
    <collision>
      <origin xyz="0 0 0" rpy="0 0 0"/>
      <geometry><sphere radius="${caster_radius}"/></geometry>
    </collision>
    <xacro:sphere_inertia m="${caster_mass}" r="${caster_radius}"/>
  </link>
  <joint name="caster_joint" type="fixed">
    <parent link="base_link"/>
    <child link="caster_wheel"/>
    <origin xyz="${-chassis_l/2+caster_radius} 0 ${-(wheel_radius-caster_radius)}" rpy="0 0 0"/>
  </joint>
  <gazebo reference="caster_wheel">
    <mu1>0.0</mu1><mu2>0.0</mu2>
  </gazebo>

  <!-- ── LiDAR link (mounted on top of chassis, centred) ── -->
  <link name="lidar_link">
    <visual>
      <origin xyz="0 0 0" rpy="0 0 0"/>
      <geometry><cylinder radius="${lidar_r}" length="${lidar_h}"/></geometry>
      <material name="black"><color rgba="0.05 0.05 0.05 1.0"/></material>
    </visual>
    <collision>
      <origin xyz="0 0 0" rpy="0 0 0"/>
      <geometry><cylinder radius="${lidar_r}" length="${lidar_h}"/></geometry>
    </collision>
    <xacro:cylinder_inertia m="${lidar_mass}" r="${lidar_r}" h="${lidar_h}"/>
  </link>

  <joint name="lidar_joint" type="fixed">
    <parent link="base_link"/>
    <child link="lidar_link"/>
    <!-- Centre on chassis top: z = chassis_h + lidar_h/2 -->
    <origin xyz="0.0 0.0 ${chassis_h + lidar_h/2}" rpy="0 0 0"/>
  </joint>

  <!-- ════════════════════════════════════════════════════════════════
       Gazebo Harmonic Plugins
       ════════════════════════════════════════════════════════════════ -->
  <gazebo>
    <!-- Differential drive -->
    <plugin filename="gz-sim-diff-drive-system"
            name="gz::sim::systems::DiffDrive">
      <left_joint>left_wheel_joint</left_joint>
      <right_joint>right_wheel_joint</right_joint>
      <wheel_separation>${wheel_sep}</wheel_separation>
      <wheel_radius>${wheel_radius}</wheel_radius>
      <odom_publish_frequency>50</odom_publish_frequency>
      <topic>/cmd_vel</topic>
      <odom_topic>/odom</odom_topic>
      <tf_topic>/tf</tf_topic>
      <frame_id>odom</frame_id>
      <child_frame_id>base_link</child_frame_id>
      <min_velocity>-1.5</min_velocity>
      <max_velocity>1.5</max_velocity>
      <min_acceleration>-3.0</min_acceleration>
      <max_acceleration>3.0</max_acceleration>
    </plugin>

    <!-- Joint state publisher -->
    <plugin filename="gz-sim-joint-state-publisher-system"
            name="gz::sim::systems::JointStatePublisher">
      <topic>/joint_states</topic>
    </plugin>
  </gazebo>

  <!-- 2D LiDAR sensor — 360° scan, 10 Hz, range 0.1–12 m -->
  <gazebo reference="lidar_link">
    <sensor name="lidar" type="gpu_lidar">
      <topic>/scan</topic>
      <update_rate>10</update_rate>
      <lidar>
        <scan>
          <horizontal>
            <samples>360</samples>
            <resolution>1</resolution>
            <min_angle>-3.14159265</min_angle>
            <max_angle>3.14159265</max_angle>
          </horizontal>
        </scan>
        <range>
          <min>0.15</min>
          <max>12.0</max>
          <resolution>0.01</resolution>
        </range>
        <noise>
          <type>gaussian</type>
          <mean>0.0</mean>
          <stddev>0.01</stddev>
        </noise>
      </lidar>
      <always_on>true</always_on>
      <visualize>true</visualize>
      <frame_id>lidar_link</frame_id>
    </sensor>
  </gazebo>

</robot>
